Workbook

Sheet ຊັ້ນຂັ້ນ
A2: ເງິນເດືອນຕາມຊັ້ນ/ຂັ້ນ | D2: ເງິນອຸດໜູນຕຳແໜ່ງ | E2: ຊົ່ວໂມງເຮັດວຽກ
A3: ຊັ້ນ/ຂັ້ນ | B3: ດັດສະນີ | C3: 9500
A4: 1/1 | B4: 260 | C4: =B4*$C$3 -> 2470000 | D4: 4200000 | E4: 0
A5: 1/2 | B5: 261 | C5: =B5*$C$3 -> 2479500 | D5: =+D4*90% -> 3780000 | E5: 1
A6: 1/3 | B6: 262 | C6: =B6*$C$3 -> 2489000 | D6: =D4*80% -> 3360000 | E6: 2
A7: 1/4 | B7: 263 | C7: =B7*$C$3 -> 2498500 | D7: 2000000 | E7: 3
A8: 1/5 | B8: 264 | C8: =B8*$C$3 -> 2508000 | D8: 1600000 | E8: 4
A9: 1/6 | B9: 265 | C9: =B9*$C$3 -> 2517500 | D9: 1300000 | E9: 5
A10: 1/7 | B10: 266 | C10: =B10*$C$3 -> 2527000 | D10: 1040000 | E10: 6
A11: 1/8 | B11: 267 | C11: =B11*$C$3 -> 2536500 | D11: 900000 | E11: 7
A12: 1/9 | B12: 268 | C12: =B12*$C$3 -> 2546000 | D12: =+D11*80% -> 720000 | E12: 8
A13: 1/10 | B13: 269 | C13: =B13*$C$3 -> 2555500 | D13: 1400000 | E13: 9
A14: 1/11 | B14: 270 | C14: =B14*$C$3 -> 2565000 | D14: 1120000 | E14: 10
A15: 1/12 | B15: 271 | C15: =B15*$C$3 -> 2574500 | D15: 910000 | E15: 11
A16: 1/13 | B16: 272 | C16: =B16*$C$3 -> 2584000 | D16: 728000 | E16: 12
A17: 1/14 | B17: 273 | C17: =B17*$C$3 -> 2593500 | D17: 630000 | E17: 13
A18: 1/15 | B18: 274 | C18: =B18*$C$3 -> 2603000 | D18: 504000 | E18: 14
A19: 2/1 | B19: 268 | C19: =B19*$C$3 -> 2546000 | D19: 0 | E19: 15
A20: 2/2 | B20: 269 | C20: =B20*$C$3 -> 2555500 | E20: 16
A21: 2/3 | B21: 270 | C21: =B21*$C$3 -> 2565000 | E21: 17
A22: 2/4 | B22: 271 | C22: =B22*$C$3 -> 2574500 | E22: 18
A23: 2/5 | B23: 272 | C23: =B23*$C$3 -> 2584000 | E23: 19
A24: 2/6 | B24: 273 | C24: =B24*$C$3 -> 2593500 | E24: 20
A25: 2/7 | B25: 274 | C25: =B25*$C$3 -> 2603000 | E25: 21
A26: 2/8 | B26: 275 | C26: =B26*$C$3 -> 2612500 | E26: 22
A27: 2/9 | B27: 276 | C27: =B27*$C$3 -> 2622000 | E27: 23
A28: 2/10 | B28: 277 | C28: =B28*$C$3 -> 2631500 | E28: 24
A29: 2/11 | B29: 278 | C29: =B29*$C$3 -> 2641000 | E29: 25
A30: 2/12 | B30: 279 | C30: =B30*$C$3 -> 2650500 | E30: 26
A31: 2/13 | B31: 280 | C31: =B31*$C$3 -> 2660000 | E31: 27
... A54: 4/6 | B54: 296 | C54: =B54*$C$3 -> 2812000 | E54: 50
A55: 4/7 | B55: 298 | C55: =B55*$C$3 -> 2831000 | E55: 51 | F55: =+C53-C50 -> 57000
A56: 4/8 | B56: 303 | C56: =B56*$C$3 -> 2878500 | E56: 52
A57: 4/9 | B57: 308 | C57: =B57*$C$3 -> 2926000 | E57: 53
A58: 4/10 | B58: 313 | C58: =B58*$C$3 -> 2973500 | E58: 54
A59: 4/11 | B59: 318 | C59: =B59*$C$3 -> 3021000 | E59: 55
A60: 4/12 | B60: 323 | C60: =B60*$C$3 -> 3068500 | E60: 56
A61: 4/13 | B61: 328 | C61: =B61*$C$3 -> 3116000 | E61: 57
A62: 4/14 | B62: 333 | C62: =B62*$C$3 -> 3163500 | E62: 58
A63: 4/15 | B63: 338 | C63: =B63*$C$3 -> 3211000 | E63: 59
...

Sheet ປີການ.
B3: ປະຕິບັດເງິນອຸດໜູນປີການ ເປັນ 4 ໄລຍະ
B4: ລ/ດ | C4: ໄລຍະ | D4: ມູນຄ່າ | E4: ປີການເຮັດວຽກ | F4: ລວມ
B5: 1 | C5: 1-5 | D5: 10000 | E5: 5 | F5: =D5*E5 -> 50000
B6: 2 | C6: 6-15 | D6: 20000 | E6: 10 | F6: =D6*E6 -> 200000
B7: 3 | C7: 16-25 | D7: 30000 | E7: 10 | F7: =D7*E7 -> 300000
B8: 4 | C8: >=26 | D8: 40000 | E8: 5 | F8: =D8*E8 -> 200000
B9: ລວມ | D9: =SUM(D5:D8) -> 100000 | E9: =SUM(E5:E8) -> 30 | F9: =SUM(F5:F8) -> 750000

Sheet ຂັ້ນເງິນເດືອນ
E1: ນະຄອນຫຼວງວຽງຈັັນ, ວັນທີ ......................................
A3: ຕາຕະລາງກຳນົດ ເງິນວິຊາການ ແລະ ອັດຕາຄ່າເງິນແຮງງານ ຂອງພະນັກງານ ພາກພື້ນດິນ ລັດວິສາຫະກິດການບິນລາວ
A4: ຕົວຢ່າງ ໂຄງຂັ້ນເງິນເດືອນ ພາກສ່ວນ ສຳນັກງານໃຫຍ່
A5: ລ/ດ | B5: ລະດັບຄວາມຊຳນານງານ | C5: ການກໍານົດລະດັບວິຊາການຄູ່ ຂະໜານ | D5: ເງິນອຸດໜູນວິຊາການ | E5: ສັດສ່ວນຕາມ | F5: usd | G5: ອັດຕາຄູນແຮງງານເພີ່ມໂມງຕໍ່ ຊມ | H5: ຊົ່ວໂມງພັນທະ | I5: ອັດຕາຄູນເງິນແຮງ
E6: ເປີເຊັນ | F6: =+'[1]Pilot stucture'!F10 -> 22324 | I6: ຕໍ່ຊົ່ວໂມງ
A7: I | B7: ຄະອໍານວຍການ ແລະ ຄະນະພະແນກ | J7: ຈຳນວນເງິນຜູ້ທີ່ທຽບເປີເຊັນ
A8: 1 | B8: ຂັ້ນ15. ຜູ້ອໍານວຍການໃຫຍ່ | D8: 24000000 | E8: 1 | F8: 936.33 | G8: 15000 | H8: 176 | I8: =+D8/H8 -> 136363.64
A9: 2 | B9: ຂັ້ນ14. ຮອງຜູ້ອໍານວຍການໃຫຍ່ | D9: =D8*E9 -> 20640000 | E9: 0.86 | F9: =+D9/$F$6 -> 924.56549 | G9: 15000 | H9: 176 | I9: =+D9/H9 -> 117272.73
A10: 3 | B10: ຂັ້ນ13. ຫົວໜ້າພະແນກການ ແລະ ຜູ້ຊ່ວຍຜູ້ອໍານວຍການ | D10: =D8*E10 -> 13920000 | E10: 0.58 | F10: =+D10/$F$6 -> 623.54417 | G10: 15000 | H10: 176 | I10: =+D10/H10 -> 79090.909
A11: 4 | B11: ຂັ້ນ12. ຮອງພະແນກ ແລະ ທີ່ປຶກສາຜູ້ອໍານວຍການ | D11: =D8*E11 -> 12000000 | E11: 0.5 | F11: =+D11/$F$6 -> 537.53808 | G11: 15000 | H11: 176 | I11: =+D11/H11 -> 68181.818
A12: 5 | B12: ຂັ້ນ11. ວິຊາການລະດັບອາຈານອາວຸໂສ | D12: =D8*E12 -> 10800000 | E12: 0.45 | F12: =+D12/$F$6 -> 483.78427 | G12: 15000 | H12: 176 | I12: =+D12/H12 -> 61363.636
A13: 6 | B13: ຂັ້ນ10. ວິຊາການລະດັບອາຈານ | D13: =D8*E13 -> 9600000 | E13: 0.4 | F13: =+D13/$F$6 -> 430.03046 | G13: 15000 | H13: 176 | I13: =+D13/H13 -> 54545.455 | J13: 0.95 | K13: 0.9 | L13: 0.7
A14: 7 | B14: ຂັ້ນ 9. ວິຊາການລະດັບປະສົບການ 3 H1 | D14: =D12*52% -> 5616000 | E14: 52% ຂອງລະດັບອາຈານອາວຸໂສ | G14: 15000 | H14: 176 | I14: =+D14/H14 -> 31909.091 | J14: =D14*$J$13 -> 5335200 | K14: =D14*$K$13 -> 5054400 | L14: =D14*$L$13 -> 3931200
A15: 8 | B15: ຂັ້ນ 8. ວິຊາການລະດັບປະສົບການ 2 H1 | C15: ອາຈານສອນ ຂັ້ນກົມການບິນ (License)/ QA Auditor | D15: =D14*E15 -> 5054400 | E15: 0.9 | G15: 15000 | H15: 176 | I15: =+D15/H15 -> 28718.182 | J15: =D15*$J$13 -> 4801680 | K15: =D15*$K$13 -> 4548960 | L15: =D15*$L$13 -> 3538080
A16: 9 | B16: ຂັ້ນ 7. ວິຊາການລະດັບປະສົບການ 1 ປີການ H1 | C16: ອາຈານສອນ ຂັ້ນຜູ້ອຳນວຍການ ( Certificate) | D16: =D14*E16 -> 4492800 | E16: 0.8 | G16: 15000 | H16: 176 | I16: =+D16/H16 -> 25527.273 | J16: =D16*$J$13 -> 4268160 | K16: =D16*$K$13 -> 4043520 | L16: =D16*$L$13 -> 3144960
A17: 10 | B17: ຂັ້ນ 6. ວິຊາການລະດັບຊໍານານງານ 3 H1 | D17: =D14*E17 -> 3931200 | E17: 0.7 | G17: 15000 | H17: 176 | I17: =+D17/H17 -> 22336.364 | J17: =D17*$J$13 -> 3734640 | K17: =D17*$K$13 -> 3538080 | L17: =D17*$L$13 -> 2751840
A18: 11 | B18: ຂັ້ນ 5. ວິຊາການລະດັບຊໍານານງານ 2 H1 | D18: =D14*E18 -> 3650400 | E18: 0.65 | G18: 15000 | H18: 176 | I18: =+D18/H18 -> 20740.909 | J18: =D18*$J$13 -> 3467880 | K18: =D18*$K$13 -> 3285360 | L18: =D18*$L$13 -> 2555280
A19: 12 | B19: ຂັ້ນ 4. ວິຊາການລະດັບຊໍານານງານ 1 H1 | C19: ຄະນະຂະແໜງ ຂັ້ນເລີ່ມຕົ້ນ | D19: =D14*E19 -> 3369600 | E19: 0.6 | G19: 15000 | H19: 176 | I19: =+D19/H19 -> 19145.455 | J19: =D19*$J$13 -> 3201120 | K19: =D19*$K$13 -> 3032640 | L19: =D19*$L$13 -> 2358720
A20: 13 | B20: ຂັ້ນ 3. ວິຊາການລະດັບສູງ H1 | D20: =D14*E20 -> 2808000 | E20: 0.5 | G20: 15000 | H20: 176 | I20: =+D20/H20 -> 15954.545 | J20: =D20*$J$13 -> 2667600 | K20: =D20*$K$13 -> 2527200 | L20: =D20*$L$13 -> 1965600
A21: 14 | B21: ຂັ້ນ 2. ວິຊາການລະດັບກາງ H1 | D21: =D14*E21 -> 2527200 | E21: 0.45 | G21: 15000 | H21: 176 | I21: =+D21/H21 -> 14359.091 | J21: =D21*$J$13 -> 2400840 | K21: =D21*$K$13 -> 2274480 | L21: =D21*$L$13 -> 1769040
A22: 15 | B22: ຂັ້ນ 1. ວິຊາການ ພື້ນຖານ H1 | D22: =D14*E22 -> 1684800 | E22: 0.3 | G22: 15000 | H22: 176 | I22: =+D22/H22 -> 9572.7273 | J22: =D22*$J$13 -> 1600560 | K22: =D22*$K$13 -> 1516320 | L22: =D22*$L$13 -> 1179360
B23: ກຸ່ມ 2 (head office group II ) | J23: 0.95 | K23: 0.9 | L23: 0.7
A24: 1 | B24: ຂັ້ນ15. ອາວຸໂສ ລະດັບ 3 H2 | E24: 95%ຂອງກຸ່ມ1 ຂັ້ນ15 | G24: 15000 | H24: 176 | I24: =+D24/H24 -> 0
A25: 2 | B25: ຂັ້ນ14. ອາວຸໂສ ລະດັບ 2 H2 | E25: 0.86 | G25: 15000 | H25: 176 | I25: =D25/H25 -> 0
A26: 3 | B26: ຂັ້ນ13. ອາວຸໂສ ລະດັບ 1 H2 | E26: 0.58 | G26: 15000 | H26: 176 | I26: =+D26/H26 -> 0
A27: 4 | B27: ຂັ້ນ12. ຊຽ່ວຊານ ລະດັບ 3 H2 | E27: 0.5 | G27: 15000 | H27: 176 | I27: =+D27/H27 -> 0
A28: 5 | B28: ຂັ້ນ11. ຊຽ່ວຊານ ລະດັບ 2 H2 | E28: 0.45 | G28: 15000 | H28: 176 | I28: =+D28/H28 -> 0
A29: 6 | B29: ຂັ້ນ10. ຊຽ່ວຊານ ລະດັບ 1 H2 | E29: 0.4 | G29: 15000 | H29: 176 | I29: =+D29/H29 -> 0
A30: 7 | B30: ຂັ້ນ 9. ວິຊາການລະດັບປະສົບການ 3 H2 | E30: 95%ຂອງກຸ່ມ1 ຂັ້ນ9 | G30: 15000 | H30: 176 | I30: =D30/H30 -> 0 | J30: =D30*$J$23 -> 0 | K30: =D30*$K$23 -> 0 | L30: =D30*$L$23 -> 0
A31: 8 | B31: ຂັ້ນ 8. ວິຊາການລະດັບປະສົບການ 2 H2 | C31: ອາຈານສອນ ຂັ້ນກົມການບິນ (License) | E31: 0.9 | G31: 15000 | H31: 176 | I31: =D31/H31 -> 0 | J31: =D31*$J$23 -> 0 | K31: =D31*$K$23 -> 0 | L31: =D31*$L$23 -> 0
A32: 9 | B32: ຂັ້ນ 7. ວິຊາການລະດັບປະສົບການ 1 H2 | C32: ອາຈານສອນ ຂັ້ນຜູ້ອຳນວຍການ ( Certificate) | E32: 0.8 | G32: 15000 | H32: 176 | I32: =D32/H32 -> 0 | J32: =D32*$J$23 -> 0 | K32: =D32*$K$23 -> 0 | L32: =D32*$L$23 -> 0
A33: 10 | B33: ຂັ້ນ 6. ວິຊາການລະດັບຊໍານານງານ 3 H2 | E33: 0.7 | G33: 15000 | H33: 176 | I33: =D33/H33 -> 0 | J33: =D33*$J$23 -> 0 | K33: =D33*$K$23 -> 0 | L33: =D33*$L$23 -> 0 | N33: =D33-D17 -> -3931200
A34: 11 | B34: ຂັ້ນ 5. ວິຊາການລະດັບຊໍານານງານ 2 H2 | E34: 0.65 | G34: 15000 | H34: 176 | I34: =D34/H34 -> 0 | J34: =D34*$J$23 -> 0 | K34: =D34*$K$23 -> 0 | L34: =D34*$L$23 -> 0
A35: 12 | B35: ຂັ້ນ 4. ວິຊາການລະດັບຊໍານານງານ 1 H2 | C35: ຄະນະຂະແໜງ ຂັ້ນເລີ່ມຕົ້ນ | E35: 0.6 | G35: 15000 | H35: 176 | I35: =D35/H35 -> 0 | J35: =D35*$J$23 -> 0 | K35: =D35*$K$23 -> 0 | L35: =D35*$L$23 -> 0
A36: 13 | B36: ຂັ້ນ 3. ວິຊາການລະດັບສູງ H2 | E36: 0.5 | G36: 15000 | H36: 176 | I36: =D36/H36 -> 0 | J36: =D36*$J$23 -> 0 | K36: =D36*$K$23 -> 0 | L36: =D36*$L$23 -> 0
A37: 14 | B37: ຂັ້ນ 2. ວິຊາການລະດັບກາງ H2 | E37: 0.45 | G37: 15000 | H37: 176 | I37: =D37/H37 -> 0 | J37: =D37*$J$23 -> 0 | K37: =D37*$K$23 -> 0 | L37: =D37*$L$23 -> 0
A38: 15 | B38: ຂັ້ນ 1. ວິຊາການ ພື້ນຖານ H2 | E38: 0.3 | G38: 15000 | H38: 176 | I38: =D38/H38 -> 0 | J38: =D38*$J$23 -> 0 | K38: =D38*$K$23 -> 0 | L38: =D38*$L$23 -> 0
B39: ກຸ່ມ 3 (head office group III ) | J39: 0.95 | K39: 0.9 | L39: 0.7
A40: 1 | B40: ຂັ້ນ15. ອາວຸໂສ ລະດັບ 3 H3 | E40: 80%ຂອງກຸ່ມ2 ຂັ້ນ 15 | G40: 15000 | H40: 176 | I40: =D40/H40 -> 0
A41: 2 | B41: ຂັ້ນ14. ອາວຸໂສ ລະດັບ 2 H3 | E41: 0.86 | G41: 15000 | H41: 176 | I41: =D41/H41 -> 0
...

Sheet Ground
A1: ສາທາລະນະລັດ ປະຊາທິປະໄຕ ປະຊາຊົນລາວ
A2: ສັນຕິພາບ ເອກະລາດ ປະຊາທິປະໄຕ ເອກະພາບ ວັດທະນະຖາວອນ
A3: ກະຊວງໂຍທາທິການ ແລະ ຂົນສົ່ງ
A4: ລັດວິສາຫະກິດ ການບິນລາວ
A5: ບັນຊີຄິດໄລ່ເງິນເດືອນໃຫ້ພະນັກງານ ລັດວິສາຫະກິດ ການບິນລາວ
A6: ຕົວຢ່າງ ໂຄງເງິນເດືອນ
A7: ລ/ດ | B7: ຊື່ ແລະ ນາມສະກຸນ | C7: ໜ້າທີ່ຕຳແໜ່ງ ບໍລິຫານ | D7: ຊັ້ນ/ຂັ້ນຕາມວຸດທິການສຶກສາ | E7: ເງິນເດືອນພື້ນຖານ | F7: ຈຳນວນປີການ | G7: ຈຳນວນເງິນ | T7: ຈຳນວນເງິນ
G8: ປີການ | H8: ຕໍາແໜ່ງ | I8: ຕຳແໜ່ງວິຊາການ | J8: ວິຊາການ | K8: ແຮງງານ ມາວຽກ | M8: ເງິນແຮງງານເຮັດວຽກເພີ້ມໂມງ | O8: ອັດຕາ/ລິດ | P8: ນຳ້ມັນ | Q8: ນະໂຍບາຍ ເຄື່ອງແບບພະນັກງານ ປະຈໍາປີ2026 | R8: ອຸດໜູນອື່ນໆ | S8: ລາຍຮັບທັງໝົດ | T8: ຈ່າຍສົມທົບ ອປສ | V8: ຫຼັງຫັກ ອປສ ທີຖືກເສຍອາກອນ | W8: ຈຳນວນອາກອນທີ່ຕ້ອງມອບ | X8: ລາຍຮັບ ຫຼັງຫັກອາກອນ | Y8: ຫັກໜີ້ອຶ່ນໆ ແລະ ເຂົ້າຄັງສັງຄົມສົງເຄາະ | Z8: ຫັກເງິນຈ່າຍລວງໜ້າ | AA8: ດັດແກ້ເພີ່ມຄືນຈາກເງິນເດືອນ | AB8: ຈຳນວນລາຍຮັບສຸດທິ
O9: 30920
K10: ຊົ່ວໂມງ ປົກກະຕິ | L10: ເປັນເງິນ | M10: ຊົ່ວໂມງ ເກີນ | N10: ເປັນເງິນ | T10: ບຸກຄົນ | U10: ບໍລິສັດ
E11: 1 | G11: 2 | H11: 3 | J11: 4 | L11: 5 | N11: 6 | P11: 7 | Q11: 8 | R11: 9 | S11: 10=1+2+3+4+5+6+7+8+9 | T11: 11=10x 5.5% | U11: 12=10x6% | V11: 13=9-10 | W11: 14 | X11: 15=13-14 | Y11: 16 | Z11: 17=8+9 | AA11: 18 | AB11: 19=15-16-17+18
D12: 0 | E12: 9585500 | F12: 88 | G12: 2170000 | H12: 5460000 | I12: 0 | J12: 70588755 | K12: 552 | L12: 70588755 | M12: 0 | N12: 0 | O12: 700 | P12: 21644000 | Q12: 0 | R12: 0 | S12: 1.8003701e+08 | T12: 742500 | U12: 810000 | V12: 1.7929451e+08 | W12: 28834133 | X12: 1.5046038e+08 | Y12: 60000 | Z12: 21644000 | AA12: 0 | AB12: 1.2875638e+08
A13: 1 | B13: ທ່ານ ກ | C13: ຫົວໜ້າຂະແໜງ | D13: 4/14 | E13: 3163500 | F13: 31 | G13: 790000 | H13: 2100000 | I13: ຂັ້ນ11. ວິຊາການລະດັບອາຈານອາວຸໂສ | J13: =ຂັ້ນເງິນເດືອນ!D12 -> 10800000 | K13: 184 | L13: =J13 -> 10800000 | N13: 0 | O13: 300 | P13: 9276000 | S13: 67252114 | T13: 247500 | U13: 270000 | V13: 67004614 | W13: 11126154 | X13: 55878460 | Y13: 20000 | Z13: 9276000 | AB13: 46582460
A14: 2 | B14: ທ່ານ ຂ | C14: ວິຊາການ | D14: 4/15 | E14: 3211000 | F14: 26 | G14: 590000 | H14: 1680000 | I14: ຂັ້ນ11. ວິຊາການລະດັບອາຈານອາວຸໂສ | J14: =ຂັ້ນເງິນເດືອນ!D12 -> 10800000 | K14: 184 | L14: =J14 -> 10800000 | N14: 0 | O14: 200 | P14: 6184000 | S14: 56292448 | T14: 247500 | U14: 270000 | V14: 56044948 | W14: 8833989.6 | X14: 47210958 | Y14: 20000 | Z14: 6184000 | AB14: 41006958

Sheet Crew
A1: ສາທາລະນະລັດ ປະຊາທິປະໄຕ ປະຊາຊົນລາວ
A2: ສັນຕິພາບ ເອກະລາດ ປະຊາທິປະໄຕ ເອກະພາບ ວັດທະນະຖາວອນ
A3: ກະຊວງໂຍທາທິການ ແລະ ຂົນສົ່ງ
A4: ລັດວິສາຫະກິດ ການບິນລາວ
A5: ບັນຊີຄິດໄລ່ເງິນເດືອນໃຫ້ພະນັກງານ ພາກສ່ວນ ຈຸບິນ ລັດວິສາຫະກິດ ການບິນລາວ
A6: =Ground!A6 -> ຕົວຢ່າງ ໂຄງເງິນເດືອນ
A7: ລ/ດ | B7: ຊື່ ແລະ ນາມສະກຸນ | C7: ໜ້າທີ່ຕຳແໜ່ງ ບໍລິຫານ | D7: ເງິນອຸດໜູນຕຳແໜ່ງ | E7: ຕຳແໜ່ງວິຊາການ | F7: ເງິນແຮງງານຕາມຊົ່ວໂມງບິນ | J7: ອັດຕາ/ລິດ | K7: ເງິນນຳ້ມັນ | L7: ເງິນນະໂຍບາຍ ເຄື່ອງແບບພະນັກງານ ປະຈໍາປີ2026 | M7: ເງິນອຸດໜູນ ອື່ນໆ | N7: ຈຳນວນເງິນລາຍຮັບທັງໝົດ | O7: ຈ່າຍສົມທົບ ອປສ | Q7: ຈຳນວນເງິນຫຼັງຫັກ ອປສ ທີຖືກເສຍອາກອນ | R7: ຈຳນວນອາກອນທີ່ຕ້ອງມອບ | S7: ຈຳນວນລາຍຮັບ ຫຼັງຫັກອາກອນ | T7: ຫັກໜີ້ອຶ່ນໆ ແລະ ເຂົ້າຄັງສັງຄົມສົງເຄາະ | U7: ຫັກເງິນຈ່າຍລວງໜ້າ | V7: ດັດແກ້ເພີ່ມຄືນຈາກເງິນເດືອນ | W7: ຈຳນວນລາຍຮັບສຸດທິ
J8: 30920
F9: ຊມ ບິນ ຕາມກຳນົດ | G9: ເປັນເງິນ | H9: ຊມ ບິນເພີ່ມ (OT) | I9: ເປັນເງິນ | O9: ບຸກຄົນ | P9: ບໍລິສັດ
O10: 0.055 | P10: 0.06
D11: 1 | G11: 2 | I11: 3 | K11: 4 | L11: 5 | M11: 6 | N11: 7=1+2+3+4+5+6 | O11: 8=7x 5.5% | P11: 9=7x6% | Q11: 10=7-8 | R11: 11 | S11: 12=10-11 | T11: 13 | U11: 14=4+5 | V11: 15 | W11: 16=12-13-14+15
B12: ນັກບິນ | D12: 12400000 | E12: 0 | F12: 2480 | G12: 4.0993444e+09 | H12: 38 | I12: 16100000 | J12: 2050 | K12: 63386000 | L12: 0 | M12: 1.3252662e+08 | N12: 4.323757e+09 | O12: 10147500 | P12: 11070000 | Q12: 4.3136095e+09 | R12: 8.4924205e+08 | S12: 3.4643675e+09 | T12: 9851221 | U12: 63386000 | V12: 0 | W12: 3.3911302e+09
A13: 1 | B13: ທ່ານ ຄ | C13: TRI/TRE Capt | D13: 1000000 | E13: DCP on Type A (A320) | F13: 52 | G13: 125639472 | I13: 0 | J13: 150 | K13: 4638000 | N13: 131277472 | O13: 247500 | P13: 270000 | Q13: 131029972 | R13: 27132493 | S13: 103897479 | T13: 20000 | U13: 4638000 | W13: 99239479
A14: 2 | B14: ທ່ານ ງ | C14: ຮອງຫົວໜ້າພະແນກ | D14: 800000 | E14: DCP on Type A (A320) | F14: 50 | G14: 125639472 | I14: 0 | J14: 130 | K14: 4019600 | M14: 10700000 | N14: 141159072 | O14: 247500 | P14: 270000 | Q14: 140911572 | R14: 29602893 | S14: 111308679 | T14: 20000 | U14: 4019600 | W14: 107269079

Sheet TEX
A1: ສາທາລະນະລັດ ປະຊາທິປະໄຕ ປະຊາຊົນລາວ
A2: ສັນຕິພາບ ເອກະລາດ ປະຊາທິປະໄຕ ເອກະພາບ ວັດທະນະຖາວອນ
A3: ກະຊວງໂຍທາທິການ ແລະ ຂົນສົ່ງ
A4: ລັດວິສາຫະກິດ ການບິນລາວ
A5: ບັນຊີຄິດໄລ່ເງິນເດືອນໃຫ້ພະນັກງານ ພະແນກວິສາວະກຳ ແລະ ສ້ອມບຳລຸງເຮືອບິນ ພາກສ່ວນ ນ່າຍຊ່າງ ລັດວິສາຫະກິດ ການບິນລາວ
A6: =Ground!A6 -> ຕົວຢ່າງ ໂຄງເງິນເດືອນ
A7: ລ/ດ | B7: ຊື່ ແລະ ນາມສະກຸນ | C7: ໜ້າທີ່ຕຳແໜ່ງ ບໍລິຫານ | D7: ຊັ້ນ/ຂັ້ນຕາມວຸດທິການສຶກສາ | E7: ເງິນເດືອນພື້ນຖານ | F7: ປີການ | G7: ເງິນອຸດໜູນປີການ | H7: ເງິນອຸດໜູນຕຳແໜ່ງ | I7: ຕຳແໜ່ງວິຊາການ | J7: ເງິນອຸດໜູນວິຊາການ | K7: ເງິນແຮງງານ ມາວຽກ | M7: ເງິນແຮງງານເຮັດວຽກເພີ້ມໂມງ | O7: ອັດຕາ/ລິດ | P7: ເງິນນ້ຳມັນ | Q7: ເງິນນະໂຍບາຍ ເຄື່ອງແບບພະນັກງານ ປະຈໍາປີ2026 | R7: ເງິນອຸດໜູນ ອື່ນໆ | S7: ຈຳນວນເງິນລາຍຮັບທັງໝົດ | T7: ຈ່າຍສົມທົບ ອປສ | V7: ຈຳນວນເງິນຫຼັງຫັກ ອປສ ທີຖືກເສຍອາກອນ | W7: ຈຳນວນອາກອນທີ່ຕ້ອງມອບ | X7: ຈຳນວນລາຍຮັບ ຫຼັງຫັກອາກອນ | Y7: ຫັກໜີ້ອຶ່ນໆ ແລະ ເຂົ້າຄັງສັງຄົມສົງເຄາະ | Z7: ຫັກເງິນຈ່າຍລວງໜ້າ | AA7: ດັດແກ້ເພີ່ມຄືນຈາກເງິນເດືອນ | AB7: ຈຳນວນລາຍຮັບສຸດທິ
O8: 30920
K9: ຊມ ປົກກະຕິ ຕົວຈິງ | L9: ເປັນເງິນ | M9: ຊມ OT | N9: ເປັນເງິນ | T9: ບຸກຄົນ | U9: ບໍລິສັດ
E10: 1 | G10: 2 | H10: 3 | J10: 4 | L10: 5 | N10: 6 | P10: 7 | Q10: 8 | R10: 9 | S10: 10 | T10: 11=10x 5.5% | U10: 12=10x 6% | V10: 13=10-11 | W10: 14 | X10: 15=13-14 | Y10: 16 | Z10: 17=7+8 | AA10: 18 | AB10: 19=15-16-17+18
B11: ພະແນກວິສາວະກຳ ແລະ ສ້ອມບຳລຸງເຮືອບິນ (ພາກສ່ວນນ່າຍຊ່າງ)
A12: 12 | B12: ທ. ຈ | C12: ຫົວໜ້າຂະແໜງສ້ອມບຳລຸງພາກສະໜາມສູນໃຫຍ່ VTE A320 | D12: 4/9 | E12: 2926000 | F12: 17 | G12: 310000 | H12: 650000 | I12: Cat ''B1&B2''Rating ( LVL5-6 Expert ) | J12: 12354907 | K12: 200 | L12: 14039667 | M12: 3 | N12: 45000 | O12: 40 | P12: 1236800 | S12: 31562374 | T12: 247500 | U12: 270000 | V12: 31314874 | W12: 3887974.7 | X12: 27426899 | Y12: 20000 | Z12: 1236800 | AB12: 26170099
A13: 14 | B13: ທ. ສ | C13: ຫົວໜ້າຂະແໜງສູນຄວບຄຸມເຕັກນິກເຮືອບິນ | D13: 4/8 | E13: 2878500 | F13: 14 | G13: 230000 | H13: 650000 | I13: Cat ''B1&B2''Rating ( LVL5-6 Expert ) | J13: 11766578 | K13: 198 | L13: 13237400 | M13: 29 | N13: 435000 | O13: 40 | P13: 1236800 | S13: 30434278 | T13: 247500 | U13: 270000 | V13: 30186778 | W13: 3662355.6 | X13: 26524422 | Y13: 755000 | Z13: 1236800 | AB13: 24532622

Sheet ຊຽ່ວຊານ
A1: ສາທາລະນະລັດ ປະຊາທິປະໄຕ ປະຊາຊົນລາວ
A2: ສັນຕິພາບ ເອກະລາດ ປະຊາທິປະໄຕ ເອກະພາບ ວັດທະນະຖາວອນ
A3: ກະຊວງໂຍທາທິການ ແລະ ຂົນສົ່ງ
A4: ລັດວິສາຫະກິດ ການບິນລາວ
A5: ບັນຊີຄິດໄລ່ເງິນເດືອນໃຫ້ ນັກບິນ,ຈຸບິນ ແລະ ພະນັກງານສັນຍາຈ້າງຊ່ຽວຊານ ຄົນຕ່າງປະເທດ
A6: =Ground!A6 -> ຕົວຢ່າງ ໂຄງເງິນເດືອນ
A7: ລ/ດ | B7: ຊື່ ແລະ ນາມສະກຸນ | C7: ໜ້າທີ່ຮັບຜິດຊອບ | R7: ເງີນໄດ້ຮັບຕົວຈິງ
D8: ເງິນເດືອນພຶ້ນຖານ ເປັນເງິນກີບ ອັດຕາແລກປ່ຽນ | E8: ຊົ່ວໂມງປົກກະຕິ (ຈຳນວນຊົ່ວໂມງເຮັດວຽກຕົວຈິງ) | F8: ຈໍານວນຊົົ່ວ ໂມງເກີນ | G8: ຄິດເປັນເງິນເກີນ | H8: ເງິນນະໂຍບາຍ ເຄື່ອງແບບພະນັກງານ ປະຈໍາປີ2026 | I8: ເງິນດັດແກ້ເພີ່ມ ແລະ ເງິນອຸດໜູນອື່ນໆ | J8: ລວມເງິນທັງໝົດເປັນເງິນກີບ | K8: ຫັກເຂົ້າປະກັນສັງຄົມ | M8: ຈໍານວນເງິນຫຼັງຫັກ ອປສ ທີຖືກເສຍອາກອນ | N8: ຈໍານວນອາກອນທີ່ຕ້ອງມອບ | O8: ລາຍຮັບຫຼັງຫັກອາກອນ | P8: ຫັກໜີ້ຕ່າງໆ | Q8: ຫັກເງິນຈ່າຍລວງໜ້າ | R8: ເປັນເງິນກີບ(LAK) | S8: ເປັນເງິນໂດລາ(USD)
K9: ບຸກຄົນ | L9: ບໍລິສັດ
D10: 22324 | K10: 0.055 | L10: 0.06
D11: 1 | G11: 2 | H11: 3 | I11: 4 | J11: 5=1+2+3+4 | K11: 6=5*5.5% | L11: 7=5*6% | M11: 8=5-6 | N11: 9 | O11: 10=8-9 | P11: 11 | Q11: 12 | R11: 13=10-11-12 | S11: 14
A12: 1 | B12: Mr. A | C12: Maintenance specialist | D12: 1.3621641e+08 | G12: 30$/h | J12: 1.3621641e+08 | K12: 247500 | L12: 270000 | M12: 1.3596891e+08 | N12: 28367227 | O12: 107601680 | Q12: 0 | R12: 107601680 | S12: 4820
A13: 2 | B13: Mr. B | C13: Commercail Specailist | D13: 59538450 | G13: 20$/h | J13: 59538450 | M13: 59538450 | N13: 9532690 | O13: 50005760 | Q13: 0 | R13: 50005760 | S13: 2240

Sheet for
A1: ສາທາລະນະລັດ ປະຊາທິປະໄຕ ປະຊາຊົນລາວ
A2: ສັນຕິພາບ ເອກະລາດ ປະຊາທິປະໄຕ ເອກະພາບ ວັດທະນະຖາວອນ
A3: ກະຊວງໂຍທາທິການ ແລະ ຂົນສົ່ງ
A4: ລັດວິສາຫະກິດ ການບິນລາວ
A5: ບັນຊີຄິດໄລ່ເງິນເດືອນໃຫ້ພະນັກງານ ລັດວິສາຫະກິດ ການບິນລາວ
A6: ປະຈຳເດືອນ ສິງຫາ (08) 2026
A7: ລ/ດ | B7: ຊື່ ແລະ ນາມສະກຸນ | C7: ໜ້າທີ່ຕຳແໜ່ງ ບໍລິຫານ | D7: ຊັ້ນ/ຂັ້ນຕາມວຸດທິການສຶກສາ | E7: ເງິນເດືອນພື້ນຖານ | F7: ປີການ | G7: ເງິນອຸດໜູນປີການ | H7: ເງິນອຸດໜູນຕຳແໜ່ງ | I7: ຕຳແໜ່ງວິຊາການ | J7: ເງິນອຸດໜູນວິຊາການ | K7: ເງິນແຮງງານ ມາວຽກ | M7: ເງິນແຮງງານເຮັດວຽກເພີ້ມໂມງ | O7: ເງິນນຳ້ມັນ | P7: ເງິນນະໂຍບາຍ ເຄື່ອງແບບພະນັກງານ ປະຈໍາປີ2026 | Q7: ເງິນອຸດໜູນອື່ນໆ | R7: ຈຳນວນເງິນລາຍຮັບທັງໝົດ | S7: ຈ່າຍສົມທົບ ອປສ | U7: ຈຳນວນເງິນຫຼັງຫັກ ອປສ ທີຖືກເສຍອາກອນ | V7: ຈຳນວນອາກອນທີ່ຕ້ອງມອບ | W7: ຈຳນວນລາຍຮັບ ຫຼັງຫັກອາກອນ | X7: ຫັກໜີ້ອຶ່ນໆ ແລະ ເຂົ້າຄັງສັງຄົມສົງເຄາະ | Y7: ຫັກເງິນຈ່າຍລວງໜ້າ | Z7: ຈຳນວນລາຍຮັບສຸດທິ
K9: ຊມ ປົກກະຕິ | L9: ເປັນເງິນ | M9: ຊມ ເກີນ | N9: ເປັນເງິນ | S9: ບຸກຄົນ | T9: ບໍລິສັດ
E10: 1 | G10: 2 | H10: 3 | J10: 4 | L10: 5 | N10: 6 | O10: 7 | P10: 8 | Q10: 9 | R10: 10=1+2+3+4+5+6+7+8+9 | S10: 9=8x5.5% | T10: 10=8x6% | U10: 11=8-9 | V10: 12 | W10: 13=11-12 | X10: 14 | Y10: 15= 7+8 | Z10: 16=13-14-15
A11: ພະນັກງານປະຈຳການຢູ່ຕ່າງປະເທດ (ຄົນລາວ) | E11: 28965500 | F11: 122 | G11: 2050000 | H11: 5710000 | I11: 0 | J11: 65462678 | K11: 1920 | L11: 65462678 | M11: 0 | N11: 0 | O11: 0 | P11: 0 | Q11: 0 | R11: 1.6765086e+08 | S11: 2475000 | T11: 2700000 | U11: 1.6517586e+08 | V11: 975334.42 | W11: 1.6420052e+08 | X11: 200000 | Y11: 0 | Z11: 1.6400052e+08
A12: 1 | B12: ທ່ານ ຊ | C12: ຫົວໜ້າ ສາຂາ | D12: 4/6 | E12: 2812000 | F12: 9 | G12: 130000 | H12: 750000 | I12: ຂັ້ນ 6. ວິຊາການລະດັບຊໍານານງານ 3 H2 | J12: 4609863.5 | K12: 192 | L12: 4609863.5 | N12: 0 | R12: 12911727 | S12: 247500 | T12: 270000 | U12: 12664227 | W12: 12664227 | X12: 20000 | Y12: 0 | Z12: 12644227
A13: 2 | B13: ທ່ານ ຍ | C13: ຜູ້ຊ່ວຍຫົວໜ້າສາຂາ | D13: 4/6 | E13: 2812000 | F13: 9 | G13: 130000 | H13: 520000 | I13: ຂັ້ນ 4. ວິຊາການລະດັບຊໍານານງານ 1 H1 | J13: 4208147.5 | K13: 192 | L13: 4208147.5 | N13: 0 | R13: 11878295 | S13: 247500 | T13: 270000 | U13: 11630795 | W13: 11630795 | X13: 20000 | Y13: 0 | Z13: 11610795
A14: ພະນັກງານທ້ອງຖິ່ນ | E14: 17611312 | F14: 0 | G14: 0 | H14: 0 | I14: 0 | J14: 0 | M14: 0 | N14: 0 | O14: 0 | P14: 0 | Q14: 0 | R14: 17611312 | S14: 0 | T14: 0 | U14: 17611312 | V14: 0 | W14: 17611312 | X14: 20000 | Y14: 0 | Z14: 17591312
A15: 1 | B15: Mr. C | C15: ຫົວໜ້າສາຂາ | E15: 17611312 | N15: 0 | R15: 17611312 | U15: 17611312 | W15: 17611312 | X15: 20000 | Y15: 0 | Z15: 17591312
A16: ພະນັກງານທ້ອງຖິ່ນ | E16: 82152320 | F16: 0 | G16: 0 | H16: 0 | I16: 0 | J16: 0 | K16: 0 | L16: 0 | M16: 0 | N16: 0 | O16: 0 | P16: 0 | Q16: 0 | R16: 82152320 | S16: 0 | T16: 0 | U16: 82152320 | V16: 0 | W16: 82152320 | X16: 100000 | Y16: 0 | Z16: 82052320
A17: 1 | B17: Mrs. D | C17: ວິຊາການ | E17: 23440200 | N17: 0 | R17: 23440200 | U17: 23440200 | W17: 23440200 | X17: 20000 | Y17: 0 | Z17: 23420200

Sheet ex.ເງິນເດືອນ
A1: ສາທາລະນະລັດ ປະຊາທິປະໄຕ ປະຊາຊົນລາວ
A2: ສັນຕິພາບ ເອກະລາດ ປະຊາທິປະໄຕ ເອກະພາບ ວັດທະນະຖາວອນ
A3: ລັດວິສາຫະກິດ ການບິນລາວ
A4: ພະແນກຈັດຕັ້ງ ແລະ ພະນັກງານ | Q4: ເລກທີ __________/ກບລ-ຈພ
Q5: ນະຄອນຫຼວງວຽງຈັນ, ວັນທີ_____________
A6: ສັງລວມບັນຊີເງິນເດືອນຂອງພະນັກງານສາຂາຕ່າງປະເທດ
A7: =[1]for!A9 -> ປະຈຳເດືອນ ສິງຫາ (08) 2026
A9: ລ/ດ | B9: ຊື່ ແລະ ນາມສະກຸນ | C9: ເງິນເດືອນພື້ນຖານ | D9: ເງິນເດືອນພື້ນຖານ | E9: ເງິນເດືອນ | F9: ເງິນເຮັດວຽກເພີ່ມໂມງ | G9: ເງິນນໍ້າມັນ | H9: ເງິນນະໂຍບາຍ ເຄື່ອງແບບພະນັກງານ ປະຈໍາປີ2026 | I9: ເງິນດັດແກ້ເພີ່ມ ແລະ ເງິນອຸດ ໜູນອື່ນໆ | J9: ລວມເງິນທັງໝົດ | K9: ຫັກເຂົ້້າປະກັນສັງຄົມ | L9: ຫັກອາກອນເງິນເດືອນ | M9: ລາຍຮັບຫລັງຫັກປະກັນສັງຄົມ ແລະ ອາກອນເງິນເດືອນ | N9: ຫັກເຂົ້າຄັງສົງເຄາະ | O9: ຫັກເງິນຈ່າຍລວງໜ້າ | P9: ລາຍຮັບຈາກເງິນເດືອນ | Q9: ອັດຕາແລກປ່ຽນ 21.08.2026 | R9: ເປັນເງິນຕາມສະກຸນ | S9: ສະກຸນເງິນ
A12: 1 | B12: ສາຂາ ບາງກອກ | E12: =+[1]BKK!H15 -> 36129317 | F12: =[1]BKK!J15 -> 0 | H12: =+[1]BKK!K15 -> 0 | J12: =+[1]BKK!M15 -> 36129317 | K12: =+[1]BKK!N15 -> 742500 | L12: =+[1]BKK!O15 -> 0 | M12: =+[1]BKK!P15 -> 35386817 | N12: =+[1]BKK!Q15 -> 60000 | O12: =+[1]BKK!R15 -> 0 | P12: =ROUND(+[1]BKK!S15,2) -> 35326817 | Q12: 677.14 | R12: =+[1]BKK!U15 -> 52170.63 | S12: THB | T12: 32134.179 | U12: =R12-T12 -> 20036.451
A13: 2 | B13: ສາຂາ ຮ່າໂນ່ຍ | E13: =+[1]HAN!H19 -> 1.0711296e+08 | F13: =[1]HAN!J19 -> 0 | H13: =+[1]HAN!K19 -> 0 | J13: =+[1]HAN!M19 -> 1.0711296e+08 | K13: =+[1]HAN!N19 -> 495000 | L13: =+[1]HAN!O19 -> 0 | M13: =+[1]HAN!P19 -> 1.0661796e+08 | N13: =+[1]HAN!Q19 -> 140000 | O13: =+[1]HAN!R19 -> 0 | P13: =ROUND(+[1]HAN!S19,2) -> 1.0647796e+08 | Q13: =[1]for!H27 -> 22324 | R13: =+[1]HAN!U19 -> 4769.65 | S13: USD | T13: 3815.942 | U13: =R13-T13 -> 953.70804
A14: 3 | B14: ສາຂາ ໂຮຈີມິງ | E14: =+[1]SGN!F13 -> 17611312 | F14: =[1]SGN!H13 -> 0 | H14: =+[1]SGN!I13 -> 0 | J14: =+[1]SGN!J13 -> 17611312 | K14: =+[1]SGN!K13 -> 0 | L14: =+[1]SGN!L13 -> 0 | M14: =+[1]SGN!M13 -> 17611312 | N14: =+[1]SGN!N13 -> 20000 | O14: =+[1]SGN!O13 -> 0 | P14: =ROUND(+[1]SGN!P13,2) -> 17591312 | Q14: =[1]for!H27 -> 22324 | R14: =+[1]SGN!R13 -> 788 | S14: USD | T14: 749.06912 | U14: =R14-T14 -> 38.930882
A15: 4 | B15: ສາຂາ ເກົາຫຼີໃຕ້ | E15: =+[1]ICN!H14 -> 68706232 | F15: =[1]ICN!J14 -> 0 | H15: =+[1]ICN!K14 -> 0 | J15: =+[1]ICN!M14 -> 68706232 | K15: =+[1]ICN!N14 -> 495000 | L15: =+[1]ICN!O14 -> 0 | M15: =+[1]ICN!P14 -> 68211232 | N15: =+[1]ICN!Q14 -> 40000 | O15: =+[1]ICN!R14 -> 0 | P15: =ROUND(+[1]ICN!S14,2) -> 68171232 | Q15: =[1]for!H27 -> 22324 | R15: =+[1]ICN!U14 -> 3053.7194 | S15: USD | T15: 1554.8808 | U15: =R15-T15 -> 1498.8386
A16: 5 | B16: ສາຂາ ຄຸນມິງ | E16: =+[1]KMG!H15 -> 43963644 | F16: =[1]KMG!J15 -> 0 | H16: =+[1]KMG!K15 -> 0 | J16: =+[1]KMG!M15 -> 43963644 | K16: =+[1]KMG!N15 -> 247500 | L16: =+[1]KMG!O15 -> 975334.42 | M16: =+[1]KMG!P15 -> 42740810 | N16: =+[1]KMG!Q15 -> 60000 | O16: =+[1]KMG!R15 -> 0 | P16: =ROUND(+[1]KMG!S15,2) -> 42680810 | Q16: =[1]for!H35 -> 3284 | R16: =+[1]KMG!U15 -> 12996.59 | S16: CNY | T16: 12853.671 | U16: =R16-T16 -> 142.91919
A17: 6 | B17: ສາຂາ ກວາງໂຈ | E17: =+[1]CAN!H15 -> 42165824 | F17: =[1]CAN!J15 -> 0 | H17: =+[1]CAN!L15 -> 0 | I17: =+[1]CAN!M15 -> 0 | J17: =+[1]CAN!N15 -> 42165824 | K17: =+[1]CAN!O15 -> 495000 | L17: =[1]CAN!P12 -> 0 | M17: =+[1]CAN!Q15 -> 41670824 | N17: =+[1]CAN!R15 -> 60000 | O17: =+[1]CAN!S15 -> 0 | P17: =ROUND(+[1]CAN!T15,2) -> 41610824 | Q17: =[1]for!H35 -> 3284 | R17: =+[1]CAN!V15 -> 12670.78 | S17: CNY | T17: 8707.1209 | U17: =R17-T17 -> 3963.6591
B18: ລວມ | E18: =SUM(E12:E17) -> 3.1568929e+08 | F18: =SUM(F12:F17) -> 0 | G18: =SUM(G12:G17) -> 0 | H18: =SUM(H12:H17) -> 0 | I18: =SUM(I12:I17) -> 0 | J18: =SUM(J12:J17) -> 3.1568929e+08 | K18: =SUM(K12:K17) -> 2475000 | L18: =SUM(L12:L17) -> 975334.42 | M18: {=SUM(ROUND(M12:M17,2))} -> 3.1223895e+08 | N18: =SUM(N12:N17) -> 380000 | O18: =SUM(O12:O17) -> 0 | P18: =SUM(P12:P17) -> 3.1185895e+08 | S18: =SUM(S13:S17) -> 0 | U18: =+R18+T18 -> 0

Sheet ex. ເງິນເຄື່ອນໄຫວ
A1: ສາທາລະນະລັດ ປະຊາທິປະໄຕ ປະຊາຊົນລາວ
A2: ສັນຕິພາບ ເອກະລາດ ປະຊາທິປະໄຕ ເອກະພາບ ວັດທະນະຖາວອນ
A3: ລັດວິສາຫະກິດ ການບິນລາວ
A4: ພະແນກຈັດຕັ້ງ ແລະ ພະນັກງານ | E4: ເລກທີ __________/ກບລ-ຈພ
E5: ນະຄອນຫຼວງວຽງຈັນ, ວັນທີ_____________
A6: ສັງລວມບັນຊີຈ່າຍເງິນເຄື່ອນໄຫວ ຂອງສາຂາຕ່າງປະເທດ
A7: =[1]TBsalary!A7 -> ປະຈຳເດືອນ ສິງຫາ (08) 2026
A9: ລ/ດ | B9: ຊື່ ແລະ ນາມສະກຸນ | C9: ເງິນເຄື່ອນໄຫວຢູ່ສາຂາ | D9: ອັດຕາແລກປ່ຽນ | E9: ເປັນເງິນຕາມສະກຸນ | F9: ສະກຸນເງິນ
A12: 1 | B12: ສາຂາບາງກອກ | C12: =[1]PBKK!E15 -> 44431061 | D12: =[1]TBsalary!Q12 -> 677.14 | E12: =[1]PBKK!G15 -> 65615.767 | F12: THB
A13: 2 | B13: ສາຂາຮ່າໂນ່ຍ | C13: =[1]PHAN!E14 -> 27995837 | D13: =[1]for!H27 -> 22324 | E13: =+[1]PHAN!G14 -> 1254.07 | F13: USD
A14: 3 | B14: ສາຂາ ເກົາຫຼີໃຕ້ | C14: =[1]PICN!E14 -> 80466655 | D14: =[1]for!H27 -> 22324 | E14: =+[1]PICN!G14 -> 3604.49 | F14: USD
A15: 4 | B15: ສາຂາຄຸນມິງ | C15: =[1]PKMG!E13 -> 16761986 | D15: =[1]for!H35 -> 3284 | E15: =+[1]PKMG!G13 -> 5104.14 | F15: CNY
A16: 5 | B16: ສາຂາກວາງໂຈ | C16: =[1]PCAN!E14 -> 34219132 | D16: =[1]for!H35 -> 3284 | E16: =+C16/D16 -> 10419.955 | F16: CNY
B17: ລວມ | C17: =SUM(C12:C16) -> 2.0387467e+08

Sheet ex.bkk-1
A1: ສາທາລະນະລັດ ປະຊາທິປະໄຕ ປະຊາຊົນລາວ
A2: ສັນຕິພາບ ເອກະລາດ ປະຊາທິປະໄຕ ເອກະພາບ ວັດທະນະຖາວອນ
A3: ລັດວິສາຫະກິດ ການບິນລາວ
A4: ພະແນກຈັດຕັ້ງ ແລະ ພະນັກງານ | T4: ເລກທີ __________ /ກບລ-ຈພ
T5: ນະຄອນຫຼວງວຽງຈັນ, ວັນທີ_____________
A6: ບັນຊີຈ່າຍເງິນເດືອນ ຂອງສາຂາບາງກອກ
A7: =[1]TBsalary!A7 -> ປະຈຳເດືອນ ສິງຫາ (08) 2026
C8: 258.7
A9: ລ/ດ | B9: ຊື່ ແລະ ນາມສະກຸນ | C9: ໜ້າທີ່ຮັບຜິດຊອບ | D9: ລວມເງິນທັງໝົດ | E9: ເງິນເດືອນພື້ນຖານ | F9: ເງິນເດືອນ ແລະ ເງິນເຄື່ອນໄຫວ | G9: ເງິນເດືອນພື້ນຖານ ທີຄິດໄລ່ | H9: ເງິນເດືອນ | I9: ເງິນແຮງງານເຮັດວຽກເພີ່ມໂມງ | K9: ເງິນນະໂຍບາຍ ເຄື່ອງແບບພະນັກງານ ປະຈໍາປີ2026 | L9: ເງິນອຸດໜູນອື່ນໆ | M9: ລວມເງິນທັງໝົດ | N9: ຫັກເຂົ້້າປະກັນສັງຄົມ | O9: ອາກອນເງິນເດືອນ | P9: ລາຍຮັບຫລັງຫັກປະກັນສັງຄົມ ແລະ ອາກອນເງິນເດືອນ | Q9: ຫັກເຂົ້າຄັງສົງເຄາະ | R9: ຫັກລາຍຈ່າຍລວງໜ້າ | S9: ລາຍຮັບຈາກເງິນເດືອນ | T9: ອັດຕາແລກປຽ່ນ | U9: ເປັນເງິນຕາມສະກຸນ | V9: ລາຍເຊັນ ແລະ ຊື່ແຈ້ງ | Y9: ລາຍຈ່າຍທັງໝົດ | AA9: ລວມລາຍຮັບສຸດທິໃນເດືອນ
W10: ເງິນເຄື່ອນໄຫວ | X10: ລວມລາຍຮັບ
I11: ຊົ່ວໂມງ | J11: ເປັນເງິນ | U11: THB | W11: ຢູ່ສາຂາ | X11: ໃນເດືອນ | Y11: ກີບ | Z11: ບາດ
A12: 1 | B12: ທ່ານ ຊ | C12: ຫົວໜ້າ ສາຂາ | D12: =E12+W12 -> 50365.508 | E12: =M12/T12 -> 19068.032 | F12: 50000 | G12: =P12/T12 -> 18702.524 | H12: =ROUND(+[1]for!I16+[1]for!K16+[1]for!L16+[1]for!N16+[1]for!P16,2) -> 12911727 | I12: =+[1]for!Q16 -> 0 | J12: =+[1]for!R16 -> 0 | K12: =[1]for!T16 -> 0 | L12: =+[1]for!U16 -> 0 | M12: =ROUND(+H12+J12+K12+L12,2) -> 12911727 | N12: =+[1]for!W16 -> 247500 | O12: =+[1]for!AF16 -> 0 | P12: =ROUND(M12-N12-O12,2) -> 12664227 | Q12: =+[1]for!AH16 -> 20000 | R12: =+K12 -> 0 | S12: =ROUND(P12-Q12-R12,2) -> 12644227 | T12: =[1]TBsalary!Q12 -> 677.14 | U12: =ROUND(+S12/T12,2) -> 18672.99 | W12: =$F$12-$G$12 -> 31297.476 | X12: =+W12+U12 -> 49970.466 | Y12: =+N12+O12+Q12 -> 267500 | Z12: =+Y12/T12 -> 395.04386 | AA12: =+U12+W12 -> 49970.466
A13: 2 | B13: ທ່ານ ຍ | C13: ຜູ້ຊ່ວຍຫົວໜ້າສາຂາ | D13: =E13+W13 -> 32240.508 | E13: =M13/T13 -> 17541.86 | F13: 31875 | G13: =P13/T13 -> 17176.352 | H13: =ROUND(+[1]for!I17+[1]for!K17+[1]for!L17+[1]for!N17+[1]for!P17,2) -> 11878295 | I13: =+[1]for!Q17 -> 0 | J13: =+[1]for!R17 -> 0 | K13: =[1]for!T17 -> 0 | L13: =+[1]for!U17 -> 0 | M13: =ROUND(+H13+J13+K13+L13,2) -> 11878295 | N13: =+[1]for!W17 -> 247500 | O13: =+[1]for!AF17 -> 0 | P13: =ROUND(M13-N13-O13,2) -> 11630795 | Q13: =[1]for!AH17 -> 20000 | R13: =+K13 -> 0 | S13: =ROUND(P13-Q13-R13,2) -> 11610795 | T13: =T12 -> 677.14 | U13: =ROUND(+S13/T13,2) -> 17146.82 | W13: =$F$13-$G$13 -> 14698.648 | X13: =+W13+U13 -> 31845.468
B14: ລວມ | D14: =SUM(D12:D13) -> 82606.016 | E14: =SUM(E12:E13) -> 36609.892 | F14: =SUM(F12:F13) -> 81875 | H14: {=SUM(ROUND(H12:H13,2))} -> 24790022 | I14: {=SUM(ROUND(I12:I13,2))} -> 0 | J14: {=SUM(ROUND(J12:J13,2))} -> 0 | K14: {=SUM(ROUND(K12:K13,2))} -> 0 | L14: {=SUM(ROUND(L12:L13,2))} -> 0 | M14: {=SUM(ROUND(M12:M13,2))} -> 24790022 | N14: {=SUM(ROUND(N12:N13,2))} -> 495000 | O14: {=SUM(ROUND(O12:O13,2))} -> 0 | ... S14: {=SUM(ROUND(S12:S13,2))} -> 24255022 | U14: =SUM(U12:U13) -> 35819.81 | V14: =SUM(V12:V13) -> 0 | W14: =SUM(W12:W13) -> 45996.124 | X14: =SUM(X12:X13) -> 81815.934

Sheet ex.bkk-2
A1: ສາທາລະນະລັດ ປະຊາທິປະໄຕ ປະຊາຊົນລາວ
A2: ສັນຕິພາບ ເອກະລາດ ປະຊາທິປະໄຕ ເອກະພາບ ວັດທະນະຖາວອນ
A3: ລັດວິສາຫະກິດ ການບິນລາວ
A4: ພະແນກຈັດຕັ້ງ ແລະ ພະນັກງານ | H4: ເລກທີ __________ /ກບລ-ຈພ
G5: ນະຄອນຫຼວງວຽງຈັນ, ວັນທີ_____________
A6: ບັນຊີຈ່າຍເງິນເຄື່ອນໄຫວ ຂອງສາຂາບາງກອກ
A7: =[1]BKK!A7 -> ປະຈຳເດືອນ ສິງຫາ (08) 2026
C8: 258.7
A9: ລ/ດ | B9: ຊື່ ແລະ ນາມສະກຸນ | C9: ໜ້າທີ່ຮັບຜິດຊອບ | D9: ເງິນເຄື່ອນໄຫວ | E9: ເງິນເຄື່ອນໄຫວຢູ່ສາຂາ | F9: ອັດຕາແລກປຽ່ນ | G9: ເປັນເງິນຕາມສະກຸນ THB | H9: ລາຍເຊັນ ແລະ ຊື່ແຈ້ງ
J11: =20000/F12 -> 29.53599
A12: 1 | B12: ທ່ານ ຊ | C12: ຫົວໜ້າ ສາຂາ | D12: =[1]BKK!W12 -> 31297.476 | E12: =ROUND(D12*$F$12,2) -> 21192773 | F12: =[1]BKK!T12 -> 677.14 | G12: =E12/F12 -> 31297.476 | I12: =+[1]BKK!U12+[1]PBKK!G12 -> 49970.466 | J12: =20000/F12+I12 -> 50000.002 | K12: =[1]BKK!U12+[1]PBKK!G12+[1]PBKK!J11 -> 50000.002
A13: 2 | B13: ທ່ານ ຍ | C13: ຜູ້ຊ່ວຍຫົວໜ້າສາຂາ | D13: =[1]BKK!W13 -> 14698.648 | E13: =ROUND(D13*$F$12,2) -> 9953042.5 | F13: =[1]BKK!T13 -> 677.14 | G13: =E13/F13 -> 14698.648 | I13: =+[1]BKK!U13+[1]PBKK!G13 -> 31845.468 | J13: =[1]for!AH17/F13+I13 -> 31875.004 | K13: =[1]BKK!U13+[1]PBKK!G13+[1]PBKK!J11 -> 31875.004
B14: ລວມ | D14: =SUM(D12:D13) -> 45996.124 | E14: {=SUM(ROUND(E12:E13,2))} -> 31145816 | G14: =SUM(G12:G13) -> 45996.124 | H14: =SUM(H12:H13) -> 0
